Invalid HTTP_HOST header: '127.0.0.1:8000'. You may need to add '127.0.0.1' to ALLOWED_HOSTS.
Traceback (most recent call last):
  File "C:\Users\Amjad.PAVILION\Downloads\templeservicemanagement\venv\lib\site-packages\django\core\handlers\exception.py", line 55, in inner
    response = get_response(request)
  File "C:\Users\Amjad.PAVILION\Downloads\templeservicemanagement\venv\lib\site-packages\django\utils\deprecation.py", line 128, in __call__
    response = self.process_request(request)
  File "C:\Users\Amjad.PAVILION\Downloads\templeservicemanagement\venv\lib\site-packages\django\middleware\common.py", line 48, in process_request
    host = request.get_host()
  File "C:\Users\Amjad.PAVILION\Downloads\templeservicemanagement\venv\lib\site-packages\django\http\request.py", line 151, in get_host
    raise DisallowedHost(msg)
django.core.exceptions.DisallowedHost: Invalid HTTP_HOST header: '127.0.0.1:8000'. You may need to add '127.0.0.1' to ALLOWED_HOSTS.
Invalid HTTP_HOST header: '127.0.0.1:8000'. You may need to add '127.0.0.1' to ALLOWED_HOSTS.
Traceback (most recent call last):
  File "C:\Users\Amjad.PAVILION\Downloads\templeservicemanagement\venv\lib\site-packages\django\core\handlers\exception.py", line 55, in inner
    response = get_response(request)
  File "C:\Users\Amjad.PAVILION\Downloads\templeservicemanagement\venv\lib\site-packages\django\utils\deprecation.py", line 128, in __call__
    response = self.process_request(request)
  File "C:\Users\Amjad.PAVILION\Downloads\templeservicemanagement\venv\lib\site-packages\django\middleware\common.py", line 48, in process_request
    host = request.get_host()
  File "C:\Users\Amjad.PAVILION\Downloads\templeservicemanagement\venv\lib\site-packages\django\http\request.py", line 151, in get_host
    raise DisallowedHost(msg)
django.core.exceptions.DisallowedHost: Invalid HTTP_HOST header: '127.0.0.1:8000'. You may need to add '127.0.0.1' to ALLOWED_HOSTS.
Invalid HTTP_HOST header: 'localhost:8000'. You may need to add 'localhost' to ALLOWED_HOSTS.
Traceback (most recent call last):
  File "C:\Users\Amjad.PAVILION\Downloads\templeservicemanagement\venv\lib\site-packages\django\core\handlers\exception.py", line 55, in inner
    response = get_response(request)
  File "C:\Users\Amjad.PAVILION\Downloads\templeservicemanagement\venv\lib\site-packages\django\utils\deprecation.py", line 128, in __call__
    response = self.process_request(request)
  File "C:\Users\Amjad.PAVILION\Downloads\templeservicemanagement\venv\lib\site-packages\django\middleware\common.py", line 48, in process_request
    host = request.get_host()
  File "C:\Users\Amjad.PAVILION\Downloads\templeservicemanagement\venv\lib\site-packages\django\http\request.py", line 151, in get_host
    raise DisallowedHost(msg)
django.core.exceptions.DisallowedHost: Invalid HTTP_HOST header: 'localhost:8000'. You may need to add 'localhost' to ALLOWED_HOSTS.
Invalid HTTP_HOST header: 'localhost:8000'. You may need to add 'localhost' to ALLOWED_HOSTS.
Traceback (most recent call last):
  File "C:\Users\Amjad.PAVILION\Downloads\templeservicemanagement\venv\lib\site-packages\django\core\handlers\exception.py", line 55, in inner
    response = get_response(request)
  File "C:\Users\Amjad.PAVILION\Downloads\templeservicemanagement\venv\lib\site-packages\django\utils\deprecation.py", line 128, in __call__
    response = self.process_request(request)
  File "C:\Users\Amjad.PAVILION\Downloads\templeservicemanagement\venv\lib\site-packages\django\middleware\common.py", line 48, in process_request
    host = request.get_host()
  File "C:\Users\Amjad.PAVILION\Downloads\templeservicemanagement\venv\lib\site-packages\django\http\request.py", line 151, in get_host
    raise DisallowedHost(msg)
django.core.exceptions.DisallowedHost: Invalid HTTP_HOST header: 'localhost:8000'. You may need to add 'localhost' to ALLOWED_HOSTS.
Invalid HTTP_HOST header: '127.0.0.1:8000'. You may need to add '127.0.0.1' to ALLOWED_HOSTS.
Traceback (most recent call last):
  File "c:\Users\Amjad.PAVILION\Downloads\templeservicemanagement\venv\lib\site-packages\django\core\handlers\exception.py", line 55, in inner
    response = get_response(request)
  File "c:\Users\Amjad.PAVILION\Downloads\templeservicemanagement\venv\lib\site-packages\django\utils\deprecation.py", line 128, in __call__
    response = self.process_request(request)
  File "c:\Users\Amjad.PAVILION\Downloads\templeservicemanagement\venv\lib\site-packages\django\middleware\common.py", line 48, in process_request
    host = request.get_host()
  File "c:\Users\Amjad.PAVILION\Downloads\templeservicemanagement\venv\lib\site-packages\django\http\request.py", line 151, in get_host
    raise DisallowedHost(msg)
django.core.exceptions.DisallowedHost: Invalid HTTP_HOST header: '127.0.0.1:8000'. You may need to add '127.0.0.1' to ALLOWED_HOSTS.
Invalid HTTP_HOST header: '127.0.0.1:8000'. You may need to add '127.0.0.1' to ALLOWED_HOSTS.
Traceback (most recent call last):
  File "c:\Users\Amjad.PAVILION\Downloads\templeservicemanagement\venv\lib\site-packages\django\core\handlers\exception.py", line 55, in inner
    response = get_response(request)
  File "c:\Users\Amjad.PAVILION\Downloads\templeservicemanagement\venv\lib\site-packages\django\utils\deprecation.py", line 128, in __call__
    response = self.process_request(request)
  File "c:\Users\Amjad.PAVILION\Downloads\templeservicemanagement\venv\lib\site-packages\django\middleware\common.py", line 48, in process_request
    host = request.get_host()
  File "c:\Users\Amjad.PAVILION\Downloads\templeservicemanagement\venv\lib\site-packages\django\http\request.py", line 151, in get_host
    raise DisallowedHost(msg)
django.core.exceptions.DisallowedHost: Invalid HTTP_HOST header: '127.0.0.1:8000'. You may need to add '127.0.0.1' to ALLOWED_HOSTS.
Internal Server Error: /temple/register/
Traceback (most recent call last):
  File "C:\Users\Amjad.PAVILION\Downloads\templeservicemanagement\templeservicemanagement\venv\lib\site-packages\django\db\backends\utils.py", line 105, in _execute
    return self.cursor.execute(sql, params)
psycopg2.errors.UndefinedTable: relation "temple_registration" does not exist
LINE 1: ..."user_role", "temple_registration"."user_id" FROM "temple_re...
                                                             ^


The above exception was the direct cause of the following exception:

Traceback (most recent call last):
  File "C:\Users\Amjad.PAVILION\Downloads\templeservicemanagement\templeservicemanagement\venv\lib\site-packages\django\core\handlers\exception.py", line 55, in inner
    response = get_response(request)
  File "C:\Users\Amjad.PAVILION\Downloads\templeservicemanagement\templeservicemanagement\venv\lib\site-packages\django\core\handlers\base.py", line 197, in _get_response
    response = wrapped_callback(request, *callback_args, **callback_kwargs)
  File "C:\Users\Amjad.PAVILION\Downloads\templeservicemanagement\templeservicemanagement\temple\views.py", line 47, in register
    for w in mgn:
  File "C:\Users\Amjad.PAVILION\Downloads\templeservicemanagement\templeservicemanagement\venv\lib\site-packages\django\db\models\query.py", line 400, in __iter__
    self._fetch_all()
  File "C:\Users\Amjad.PAVILION\Downloads\templeservicemanagement\templeservicemanagement\venv\lib\site-packages\django\db\models\query.py", line 1928, in _fetch_all
    self._result_cache = list(self._iterable_class(self))
  File "C:\Users\Amjad.PAVILION\Downloads\templeservicemanagement\templeservicemanagement\venv\lib\site-packages\django\db\models\query.py", line 91, in __iter__
    results = compiler.execute_sql(
  File "C:\Users\Amjad.PAVILION\Downloads\templeservicemanagement\templeservicemanagement\venv\lib\site-packages\django\db\models\sql\compiler.py", line 1574, in execute_sql
    cursor.execute(sql, params)
  File "C:\Users\Amjad.PAVILION\Downloads\templeservicemanagement\templeservicemanagement\venv\lib\site-packages\django\db\backends\utils.py", line 79, in execute
    return self._execute_with_wrappers(
  File "C:\Users\Amjad.PAVILION\Downloads\templeservicemanagement\templeservicemanagement\venv\lib\site-packages\django\db\backends\utils.py", line 92, in _execute_with_wrappers
    return executor(sql, params, many, context)
  File "C:\Users\Amjad.PAVILION\Downloads\templeservicemanagement\templeservicemanagement\venv\lib\site-packages\django\db\backends\utils.py", line 100, in _execute
    with self.db.wrap_database_errors:
  File "C:\Users\Amjad.PAVILION\Downloads\templeservicemanagement\templeservicemanagement\venv\lib\site-packages\django\db\utils.py", line 91, in __exit__
    raise dj_exc_value.with_traceback(traceback) from exc_value
  File "C:\Users\Amjad.PAVILION\Downloads\templeservicemanagement\templeservicemanagement\venv\lib\site-packages\django\db\backends\utils.py", line 105, in _execute
    return self.cursor.execute(sql, params)
django.db.utils.ProgrammingError: relation "temple_registration" does not exist
LINE 1: ..."user_role", "temple_registration"."user_id" FROM "temple_re...
                                                             ^

"POST /temple/register/ HTTP/1.1" 500 145
